Workbook

Sheet State RF
A1: Claude | H1: GPT-4o | O1: Deepseek-r1 | V1: ALL
A3: OOB estimate of error rate: 27.35% | H3: OOB estimate of error rate: 21.86% | O3: OOB estimate of error rate: 28.82% | V3: OOB estimate of error rate: 25.91%
A4: Confusion matrix: | H4: Confusion matrix: | O4: Confusion matrix: | V4: Confusion matrix:
A5: 0 1 class.error | H5: 0 1 class.error | O5: 0 1 class.error | V5: 0 1 class.error
A6: 0 2600 968 0.2713004 | H6: 0 2981 828 0.2173799 | O6: 0 2238 871 0.2801544 | V6: 0 8390 2978 0.2619634
A7: 1 967 2539 0.2758129 | H7: 1 841 2986 0.2197544 | O7: 1 912 2165 0.2963926 | V7: 1 2900 8421 0.2561611
A9: Rank | B9: LIWC_Variable | C9: 0 | D9: 1 | E9: MeanDecreaseAccuracy | F9: MeanDecreaseGini | I9: LIWC_Variable | J9: 0 | K9: 1 | L9: MeanDecreaseAccuracy | M9: MeanDecreaseGini | O9: Rank | P9: LIWC_Variable | Q9: 0 | R9: 1 | S9: MeanDecreaseAccuracy | T9: MeanDecreaseGini | V9: Rank | W9: LIWC_Variable | X9: 0 | Y9: 1 | Z9: MeanDecreaseAccuracy | AA9: MeanDecreaseGini
A11: 1 | B11: assent | C11: 32.667203 | D11: 31.146214 | E11: 40.404524 | F11: 128.47384 | H11: 1 | I11: moral | J11: 16.09564 | K11: 39.775043 | L11: 42.560108 | M11: 148.62923 | O11: 1 | P11: moral | Q11: 16.09564 | R11: 39.775043 | S11: 42.560108 | T11: 148.62923 | V11: 1 | W11: negate | X11: 45.295954 | Y11: 37.500648 | Z11: 52.886381 | AA11: 483.93962
A12: 2 | B12: negate | C12: 21.05573 | D12: 27.097793 | E12: 32.742875 | F12: 121.11304 | H12: 2 | I12: negate | J12: 25.675694 | K12: 33.613884 | L12: 38.470366 | M12: 149.55089 | O12: 2 | P12: negate | Q12: 25.675694 | R12: 33.613884 | S12: 38.470366 | T12: 149.55089 | V12: 2 | W12: moral | X12: 32.903723 | Y12: 47.518702 | Z12: 52.376816 | AA12: 356.60713
A13: 3 | B13: we | C13: 23.792125 | D13: 20.870867 | E13: 31.749899 | F13: 100.5445 | H13: 3 | I13: insight | J13: 10.117555 | K13: 32.729106 | L13: 33.448917 | M13: 121.96991 | O13: 3 | P13: insight | Q13: 10.117555 | R13: 32.729106 | S13: 33.448917 | T13: 121.96991 | V13: 3 | W13: risk | X13: 39.706314 | Y13: 38.057304 | Z13: 48.236903 | AA13: 341.02192
A14: 4 | B14: risk | C14: 21.708053 | D14: 23.784444 | E14: 28.68349 | F14: 95.703902 | H14: 4 | I14: risk | J14: 26.658317 | K14: 27.182612 | L14: 32.947576 | M14: 116.2766 | O14: 4 | P14: risk | Q14: 26.658317 | R14: 27.182612 | S14: 32.947576 | T14: 116.2766 | V14: 4 | W14: assent | X14: 39.401608 | Y14: 34.452472 | Z14: 45.347681 | AA14: 265.60959
A15: 5 | B15: moral | C15: 15.321183 | D15: 20.027598 | E15: 23.183604 | F15: 74.017418 | H15: 5 | I15: adj | J15: 19.909043 | K15: 20.115162 | L15: 27.55109 | M15: 121.39542 | O15: 5 | P15: adj | Q15: 19.909043 | R15: 20.115162 | S15: 27.55109 | T15: 121.39542 | V15: 5 | W15: we | X15: 39.28864 | Y15: 33.076004 | Z15: 44.081964 | AA15: 313.11722
A16: 6 | B16: affiliation | C16: 8.852501 | D16: 17.641109 | E16: 21.219061 | F16: 85.336854 | H16: 6 | I16: cause | J16: 20.887996 | K16: 20.272273 | L16: 26.878028 | M16: 129.28142 | O16: 6 | P16: cause | Q16: 20.887996 | R16: 20.272273 | S16: 26.878028 | T16: 129.28142 | V16: 6 | W16: differ | X16: 32.74789 | Y16: 23.80377 | Z16: 38.85531 | AA16: 368.18114
A17: 7 | B17: adj | C17: 18.921008 | D17: 11.911248 | E17: 21.210044 | F17: 110.75784 | H17: 7 | I17: differ | J17: 23.365447 | K17: 14.546694 | L17: 26.311559 | M17: 120.07361 | O17: 7 | P17: differ | Q17: 23.365447 | R17: 14.546694 | S17: 26.311559 | T17: 120.07361 | V17: 7 | W17: adj | X17: 28.292803 | Y17: 26.144548 | Z17: 35.619082 | AA17: 358.62962
A18: 8 | B18: Clout | C18: 11.028873 | D18: 16.812598 | E18: 20.26968 | F18: 89.763372 | H18: 8 | I18: assent | J18: 18.14412 | K18: 23.742133 | L18: 26.090863 | M18: 77.194716 | O18: 8 | P18: assent | Q18: 18.14412 | R18: 23.742133 | S18: 26.090863 | T18: 77.194716 | V18: 8 | W18: affiliation | X18: 3.554408 | Y18: 33.260038 | Z18: 33.859073 | AA18: 253.77492
A19: 9 | B19: power | C19: 14.930312 | D19: 13.066653 | E19: 19.567703 | F19: 88.59832 | H19: 9 | I19: Clout | J19: 10.988572 | K19: 23.343181 | L19: 25.0837 | M19: 105.56674 | O19: 9 | P19: Clout | Q19: 10.988572 | R19: 23.343181 | S19: 25.0837 | T19: 105.56674 | V19: 9 | W19: Clout | X19: 20.804901 | Y19: 21.452557 | Z19: 30.484078 | AA19: 290.41788
A20: 10 | B20: tone_pos | C20: 9.7884964 | D20: 16.346107 | E20: 18.981453 | F20: 88.132555 | H20: 10 | I20: tone_pos | J20: 7.907367 | K20: 18.910708 | L20: 24.006274 | M20: 82.794549 | O20: 10 | P20: tone_pos | Q20: 7.907367 | R20: 18.910708 | S20: 24.006274 | T20: 82.794549 | V20: 10 | W20: Tone | X20: 23.225961 | Y20: 19.410088 | Z20: 30.322167 | AA20: 266.34236
A21: 11 | B21: Tone | C21: 11.221161 | D21: 14.049368 | E21: 18.49341 | F21: 87.988751 | H21: 11 | I21: affiliation | J21: 4.967523 | K21: 23.055603 | L21: 23.573993 | M21: 77.259355 | O21: 11 | P21: affiliation | Q21: 4.967523 | R21: 23.055603 | S21: 23.573993 | T21: 77.259355 | V21: 11 | W21: insight | X21: 17.638498 | Y21: 27.892237 | Z21: 30.305869 | AA21: 291.17328
A22: 12 | B22: cause | C22: 13.80804 | D22: 11.243249 | E22: 17.726837 | F22: 96.64823 | H22: 12 | I22: quantity | J22: 16.765102 | K22: 18.106515 | L22: 23.213898 | M22: 107.28115 | O22: 12 | P22: quantity | Q22: 16.765102 | R22: 18.106515 | S22: 23.213898 | T22: 107.28115 | V22: 12 | W22: tentat | X22: 20.685555 | Y22: 26.281015 | Z22: 29.877393 | AA22: 302.14828
... A71: 61 | B71: swear | C71: -0.5881032 | D71: 0.9830698 | E71: 0.3585934 | F71: 0.29556051 | H71: 61 | I71: filler | J71: 0 | K71: 0 | L71: 0 | M71: 0 | O71: 61 | P71: filler | Q71: 0 | R71: 0 | S71: 0 | T71: 0 | V71: 61 | W71: filler | X71: 0 | Y71: 0 | Z71: 0 | AA71: 0.09397926
A72: 62 | B72: filler | C72: 0 | D72: 0 | E72: 0 | F72: 0.03783358 | H72: 62 | I72: swear | J72: -1.417049 | K72: 1.001002 | L72: -0.5710774 | M72: 0.1149475 | O72: 62 | P72: swear | Q72: -1.417049 | R72: 1.001002 | S72: -0.5710774 | T72: 0.1149475 | V72: Showing 1 to 15 of 61 entries, 5 total columns
A73: Showing 1 to 21 of 62 entries, 5 total columns | H73: Showing 1 to 21 of 62 entries, 5 total columns | O73: Showing 1 to 21 of 62 entries, 5 total columns

Sheet State GLM
A1: ROUND 1 - TOP 20 VARIABLES MINUS HIGHLY CORRELATED ONES
A2: Claude | I2: GPT-4o | Q2: Deepseek-r1
A3: Correlations | B3: Tone, tone_neg, tone_pos | I3: Correlations | J3: Tone, tone_pos | O3: ` | Q3: Correlations | AA3: Claude | AC3: GPT-4o | AE3: DeepSeek-R1 | AG3: Overall
A4: AUC | B4: 0.7176 | I4: AUC | J4: 0.7083 | Q4: AUC | R4: 0.6903 | AA4: Std Coefficient | AB4: Rank | AC4: Std Coefficient | AD4: Rank | AE4: Std Coefficient | AF4: Rank | AG4: Rank
Y5: Common Variables Across Models | Z5: we | AA5: =IFERROR(VLOOKUP($Z5,$B$8:$C$28,2,FALSE),NA()) -> 0.35914908 | AB5: =IFERROR(MATCH($Z5,$B$9:$B$28,0),NA()) -> 2 | AC5: =IFERROR(VLOOKUP($Z5,$J$8:$K$28,2,FALSE),NA()) -> 0.24838455 | AD5: =IFERROR(MATCH($Z5,$J$9:$J$28,0),NA()) -> 6 | AE5: =IFERROR(VLOOKUP($Z5,$R$8:$S$28,2,FALSE),NA()) -> 0.33452618 | AF5: =IFERROR(MATCH($Z5,$R$9:$R$28,0),NA()) -> 1 | AG5: =AVERAGE(AF5,AD5,AB5) -> 3
A6: Rank | B6: Parameter | C6: Std_Coefficient | D6: CI | E6: CI_low | F6: CI_high | G6: abs_coef | I6: Rank | J6: Parameter | K6: Std_Coefficient | L6: CI | M6: CI_low | N6: CI_high | O6: abs_coef | Q6: Rank | R6: Parameter | S6: Std_Coefficient | T6: CI | U6: CI_low | V6: CI_high | W6: abs_coef | Z6: assent | AA6: =IFERROR(VLOOKUP($Z6,$B$8:$C$28,2,FALSE),NA()) -> -0.50740323 | AB6: =IFERROR(MATCH($Z6,$B$9:$B$28,0),NA()) -> 1 | AC6: =IFERROR(VLOOKUP($Z6,$J$8:$K$28,2,FALSE),NA()) -> -0.35695858 | AD6: =IFERROR(MATCH($Z6,$J$9:$J$28,0),NA()) -> 1 | AE6: =IFERROR(VLOOKUP($Z6,$R$8:$S$28,2,FALSE),NA()) -> -0.16268429 | AF6: =IFERROR(MATCH($Z6,$R$9:$R$28,0),NA()) -> 8 | AG6: =AVERAGE(AF6,AD6,AB6) -> 3.3333333
Z7: negate | AA7: =IFERROR(VLOOKUP($Z7,$B$8:$C$28,2,FALSE),NA()) -> 0.23510961 | AB7: =IFERROR(MATCH($Z7,$B$9:$B$28,0),NA()) -> 5 | AC7: =IFERROR(VLOOKUP($Z7,$J$8:$K$28,2,FALSE),NA()) -> 0.25782954 | AD7: =IFERROR(MATCH($Z7,$J$9:$J$28,0),NA()) -> 5 | AE7: =IFERROR(VLOOKUP($Z7,$R$8:$S$28,2,FALSE),NA()) -> 0.1851472 | AF7: =IFERROR(MATCH($Z7,$R$9:$R$28,0),NA()) -> 5 | AG7: =AVERAGE(AF7,AD7,AB7) -> 5
A8: 1 | B8: (Intercept) | C8: 0.98126401 | D8: 0.95 | E8: 0.93772961 | F8: 1.0251716 | G8: 0.98126401 | I8: 1 | J8: (Intercept) | K8: 0.50880905 | L8: 0.95 | M8: 0.46937034 | N8: 0.54841359 | O8: 0.50880905 | Q8: 1 | R8: (Intercept) | S8: 1.2046776 | T8: 0.95 | U8: 1.1593864 | V8: 1.2504603 | W8: 1.2046776 | Z8: Tone | AA8: =IFERROR(VLOOKUP($Z8,$B$8:$C$28,2,FALSE),NA()) -> -0.24086748 | AB8: =IFERROR(MATCH($Z8,$B$9:$B$28,0),NA()) -> 4 | AC8: =IFERROR(VLOOKUP($Z8,$J$8:$K$28,2,FALSE),NA()) -> 0.28974849 | AD8: =IFERROR(MATCH($Z8,$J$9:$J$28,0),NA()) -> 3 | AE8: =IFERROR(VLOOKUP($Z8,$R$8:$S$28,2,FALSE),NA()) -> 0.13072843 | AF8: =IFERROR(MATCH($Z8,$R$9:$R$28,0),NA()) -> 10 | AG8: =AVERAGE(AF8,AD8,AB8) -> 5.6666667
A9: 2 | B9: assent | C9: -0.50740323 | D9: 0.95 | E9: -0.55126144 | F9: -0.46399141 | G9: 0.50740323 | I9: 2 | J9: assent | K9: -0.35695858 | L9: 0.95 | M9: -0.39676892 | N9: -0.3173945 | O9: 0.35695858 | Q9: 2 | R9: we | S9: 0.33452618 | T9: 0.95 | U9: 0.27082945 | V9: 0.39959931 | W9: 0.33452618 | Z9: adj | AA9: =IFERROR(VLOOKUP($Z9,$B$8:$C$28,2,FALSE),NA()) -> -0.21287331 | AB9: =IFERROR(MATCH($Z9,$B$9:$B$28,0),NA()) -> 7 | AC9: =IFERROR(VLOOKUP($Z9,$J$8:$K$28,2,FALSE),NA()) -> -0.16214955 | AD9: =IFERROR(MATCH($Z9,$J$9:$J$28,0),NA()) -> 8 | AE9: =IFERROR(VLOOKUP($Z9,$R$8:$S$28,2,FALSE),NA()) -> -0.21250964 | AF9: =IFERROR(MATCH($Z9,$R$9:$R$28,0),NA()) -> 3 | AG9: =AVERAGE(AF9,AD9,AB9) -> 6
A10: 3 | B10: we | C10: 0.35914908 | D10: 0.95 | E10: 0.29415367 | F10: 0.42496722 | G10: 0.35914908 | I10: 3 | J10: cause | K10: 0.33276253 | L10: 0.95 | M10: 0.28844081 | N10: 0.37738786 | O10: 0.33276253 | Q10: 3 | R10: moral | S10: 0.30856134 | T10: 0.95 | U10: 0.24857526 | V10: 0.36952006 | W10: 0.30856134 | Z10: moral | AA10: =IFERROR(VLOOKUP($Z10,$B$8:$C$28,2,FALSE),NA()) -> 0.10767296 | AB10: =IFERROR(MATCH($Z10,$B$9:$B$28,0),NA()) -> 13 | AC10: =IFERROR(VLOOKUP($Z10,$J$8:$K$28,2,FALSE),NA()) -> 0.16765866 | AD10: =IFERROR(MATCH($Z10,$J$9:$J$28,0),NA()) -> 7 | AE10: =IFERROR(VLOOKUP($Z10,$R$8:$S$28,2,FALSE),NA()) -> 0.30856134 | AF10: =IFERROR(MATCH($Z10,$R$9:$R$28,0),NA()) -> 2 | AG10: =AVERAGE(AF10,AD10,AB10) -> 7.3333333
A11: 4 | B11: you | C11: -0.27315663 | D11: 0.95 | E11: -0.33654639 | F11: -0.20998332 | G11: 0.27315663 | I11: 4 | J11: Tone | K11: 0.28974849 | L11: 0.95 | M11: 0.15138635 | N11: 0.42849586 | O11: 0.28974849 | Q11: 4 | R11: adj | S11: -0.21250964 | T11: 0.95 | U11: -0.25778465 | V11: -0.16731267 | W11: 0.21250964 | Z11: Clout | AA11: =IFERROR(VLOOKUP($Z11,$B$8:$C$28,2,FALSE),NA()) -> 0.0893056 | AB11: =IFERROR(MATCH($Z11,$B$9:$B$28,0),NA()) -> 14 | AC11: =IFERROR(VLOOKUP($Z11,$J$8:$K$28,2,FALSE),NA()) -> -0.2680447 | AD11: =IFERROR(MATCH($Z11,$J$9:$J$28,0),NA()) -> 4 | AE11: =IFERROR(VLOOKUP($Z11,$R$8:$S$28,2,FALSE),NA()) -> -0.18020407 | AF11: =IFERROR(MATCH($Z11,$R$9:$R$28,0),NA()) -> 6 | AG11: =AVERAGE(AF11,AD11,AB11) -> 8
A12: 5 | B12: Tone | C12: -0.24086748 | D12: 0.95 | E12: -0.40315442 | F12: -0.07943336 | G12: 0.24086748 | I12: 5 | J12: Clout | K12: -0.2680447 | L12: 0.95 | M12: -0.3278088 | N12: -0.20835588 | O12: 0.2680447 | Q12: 5 | R12: insight | S12: 0.20976486 | T12: 0.95 | U12: 0.15677967 | V12: 0.26324196 | W12: 0.20976486 | Z12: risk | AA12: =IFERROR(VLOOKUP($Z12,$B$8:$C$28,2,FALSE),NA()) -> -0.1825369 | AB12: =IFERROR(MATCH($Z12,$B$9:$B$28,0),NA()) -> 8 | AC12: =IFERROR(VLOOKUP($Z12,$J$8:$K$28,2,FALSE),NA()) -> -0.15142174 | AD12: =IFERROR(MATCH($Z12,$J$9:$J$28,0),NA()) -> 9 | AE12: =IFERROR(VLOOKUP($Z12,$R$8:$S$28,2,FALSE),NA()) -> -0.15817969 | AF12: =IFERROR(MATCH($Z12,$R$9:$R$28,0),NA()) -> 9 | AG12: =AVERAGE(AF12,AD12,AB12) -> 8.6666667
A13: 6 | B13: negate | C13: 0.23510961 | D13: 0.95 | E13: 0.18593418 | F13: 0.28463036 | G13: 0.23510961 | I13: 6 | J13: negate | K13: 0.25782954 | L13: 0.95 | M13: 0.20635263 | N13: 0.30970055 | O13: 0.25782954 | Q13: 6 | R13: negate | S13: 0.1851472 | T13: 0.95 | U13: 0.13017017 | V13: 0.24037163 | W13: 0.1851472 | Y13: Model Specific Variables | Z13: tone_neg* | AA13: =IFERROR(VLOOKUP($Z13,$B$8:$C$28,2,FALSE),NA()) -> -0.17848925 | AB13: =IFERROR(MATCH($Z13,$B$9:$B$28,0),NA()) -> 9 | AC13: =IFERROR(VLOOKUP($Z13,$J$8:$K$28,2,FALSE),NA()) -> -0.090600478 | AD13: =IFERROR(MATCH($Z13,$J$9:$J$28,0),NA()) -> 15 | AE13: =IFERROR(VLOOKUP($Z13,$R$8:$S$28,2,FALSE),NA()) -> -0.081345928 | AF13: =IFERROR(MATCH($Z13,$R$9:$R$28,0),NA()) -> 13 | AG13: =AVERAGE(AF13,AD13,AB13) -> 12.333333
A14: 7 | B14: tone_pos | C14: 0.22888273 | D14: 0.95 | E14: 0.08932636 | F14: 0.36966827 | G14: 0.22888273 | I14: 7 | J14: we | K14: 0.24838455 | L14: 0.95 | M14: 0.19942763 | N14: 0.29871727 | O14: 0.24838455 | Q14: 7 | R14: Clout | S14: -0.18020407 | T14: 0.95 | U14: -0.24074391 | V14: -0.11954116 | W14: 0.18020407 | Z14: differ | AA14: =IFERROR(VLOOKUP($Z14,$B$8:$C$28,2,FALSE),NA()) -> 0.14187859 | AB14: =IFERROR(MATCH($Z14,$B$9:$B$28,0),NA()) -> 10 | AC14: =IFERROR(VLOOKUP($Z14,$J$8:$K$28,2,FALSE),NA()) -> -0.14232761 | AD14: =IFERROR(MATCH($Z14,$J$9:$J$28,0),NA()) -> 10 | AE14: =IFERROR(VLOOKUP($Z14,$R$8:$S$28,2,FALSE),NA()) -> 0.022513669 | AF14: =IFERROR(MATCH($Z14,$R$9:$R$28,0),NA()) -> 19 | AG14: =AVERAGE(AF14,AD14,AB14) -> 13
A15: 8 | B15: adj | C15: -0.21287331 | D15: 0.95 | E15: -0.25871729 | F15: -0.16712995 | G15: 0.21287331 | I15: 8 | J15: moral | K15: 0.16765866 | L15: 0.95 | M15: 0.12102878 | N15: 0.2147788 | O15: 0.16765866 | Q15: 8 | R15: quantity | S15: 0.1681268 | T15: 0.95 | U15: 0.11730925 | V15: 0.2195894 | W15: 0.1681268 | Z15: affiliation | AA15: =IFERROR(VLOOKUP($Z15,$B$8:$C$28,2,FALSE),NA()) -> -0.0389662 | AB15: =IFERROR(MATCH($Z15,$B$9:$B$28,0),NA()) -> 18 | AC15: =IFERROR(VLOOKUP($Z15,$J$8:$K$28,2,FALSE),NA()) -> -0.1071933 | AD15: =IFERROR(MATCH($Z15,$J$9:$J$28,0),NA()) -> 13 | AE15: =IFERROR(VLOOKUP($Z15,$R$8:$S$28,2,FALSE),NA()) -> -0.10372342 | AF15: =IFERROR(MATCH($Z15,$R$9:$R$28,0),NA()) -> 12 | AG15: =AVERAGE(AF15,AD15,AB15) -> 14.333333
A16: 9 | B16: risk | C16: -0.1825369 | D16: 0.95 | E16: -0.22672357 | F16: -0.1384384 | G16: 0.1825369 | I16: 9 | J16: adj | K16: -0.16214955 | L16: 0.95 | M16: -0.20541219 | N16: -0.11897229 | O16: 0.16214955 | Q16: 9 | R16: assent | S16: -0.16268429 | T16: 0.95 | U16: -0.20472521 | V16: -0.12050798 | W16: 0.16268429 | Z16: prosocial | AA16: =IFERROR(VLOOKUP($Z16,$B$8:$C$28,2,FALSE),NA()) -> 0.12894532 | AB16: =IFERROR(MATCH($Z16,$B$9:$B$28,0),NA()) -> 12 | AC16: =IFERROR(VLOOKUP($Z16,$J$8:$K$28,2,FALSE),NA()) -> 0.0111523 | AD16: =IFERROR(MATCH($Z16,$J$9:$J$28,0),NA()) -> 19 | AE16: =IFERROR(VLOOKUP($Z16,$R$8:$S$28,2,FALSE),NA()) -> 0.069417091 | AF16: =IFERROR(MATCH($Z16,$R$9:$R$28,0),NA()) -> 14 | AG16: =AVERAGE(AF16,AD16,AB16) -> 15
A17: 10 | B17: tone_neg | C17: -0.17848925 | D17: 0.95 | E17: -0.27372775 | F17: -0.083489265 | G17: 0.17848925 | I17: 10 | J17: risk | K17: -0.15142174 | L17: 0.95 | M17: -0.19449301 | N17: -0.10860033 | O17: 0.15142174 | Q17: 10 | R17: risk | S17: -0.15817969 | T17: 0.95 | U17: -0.20421853 | V17: -0.11213647 | W17: 0.15817969 | Z17: power | AA17: =IFERROR(VLOOKUP($Z17,$B$8:$C$28,2,FALSE),NA()) -> -0.01538221 | AB17: =IFERROR(MATCH($Z17,$B$9:$B$28,0),NA()) -> 19 | AC17: =IFERROR(VLOOKUP($Z17,$J$8:$K$28,2,FALSE),NA()) -> 0.041216283 | AD17: =IFERROR(MATCH($Z17,$J$9:$J$28,0),NA()) -> 17 | AE17: =IFERROR(VLOOKUP($Z17,$R$8:$S$28,2,FALSE),NA()) -> 0.030318544 | AF17: =IFERROR(MATCH($Z17,$R$9:$R$28,0),NA()) -> 17 | AG17: =AVERAGE(AF17,AD17,AB17) -> 17.666667
A18: 11 | B18: differ | C18: 0.14187859 | D18: 0.95 | E18: 0.08416136 | F18: 0.19982405 | G18: 0.14187859 | I18: 11 | J18: differ | K18: -0.14232761 | L18: 0.95 | M18: -0.19536914 | N18: -0.08934931 | O18: 0.14232761 | Q18: 11 | R18: Tone | S18: 0.13072843 | T18: 0.95 | U18: 0.062103925 | V18: 0.19984763 | W18: 0.13072843 | Z18: you | AA18: =IFERROR(VLOOKUP($Z18,$B$8:$C$28,2,FALSE),NA()) -> -0.27315663 | AB18: =IFERROR(MATCH($Z18,$B$9:$B$28,0),NA()) -> 3 | AC18: =IFERROR(VLOOKUP($Z18,$J$8:$K$28,2,FALSE),NA()) -> #N/A | AD18: =IFERROR(MATCH($Z18,$J$9:$J$28,0),NA()) -> #N/A | AE18: =IFERROR(VLOOKUP($Z18,$R$8:$S$28,2,FALSE),NA()) -> #N/A | AF18: =IFERROR(MATCH($Z18,$R$9:$R$28,0),NA()) -> #N/A | AG18: =AVERAGE(AF18,AD18,AB18) -> #N/A
A19: 12 | B19: cause | C19: 0.1316208 | D19: 0.95 | E19: 0.08681892 | F19: 0.17668016 | G19: 0.1316208 | I19: 12 | J19: tone_pos | K19: -0.13779336 | L19: 0.95 | M19: -0.260723 | N19: -0.01515905 | O19: 0.13779336 | Q19: 12 | R19: allure | S19: -0.11643369 | T19: 0.95 | U19: -0.16249986 | V19: -0.07028193 | W19: 0.11643369 | Z19: tone_pos | AA19: =IFERROR(VLOOKUP($Z19,$B$8:$C$28,2,FALSE),NA()) -> 0.22888273 | AB19: =IFERROR(MATCH($Z19,$B$9:$B$28,0),NA()) -> 6 | AC19: =IFERROR(VLOOKUP($Z19,$J$8:$K$28,2,FALSE),NA()) -> -0.13779336 | AD19: =IFERROR(MATCH($Z19,$J$9:$J$28,0),NA()) -> 11 | AE19: =IFERROR(VLOOKUP($Z19,$R$8:$S$28,2,FALSE),NA()) -> #N/A | AF19: =IFERROR(MATCH($Z19,$R$9:$R$28,0),NA()) -> #N/A | AG19: =AVERAGE(AF19,AD19,AB19) -> #N/A
A20: 13 | B20: prosocial | C20: 0.12894532 | D20: 0.95 | E20: 0.07356252 | F20: 0.18482953 | G20: 0.12894532 | I20: 13 | J20: Authentic | K20: -0.12089198 | L20: 0.95 | M20: -0.17629703 | N20: -0.06545284 | O20: 0.12089198 | Q20: 13 | R20: affiliation | S20: -0.10372342 | T20: 0.95 | U20: -0.17445429 | V20: -0.03260882 | W20: 0.10372342 | Z20: cause | AA20: =IFERROR(VLOOKUP($Z20,$B$8:$C$28,2,FALSE),NA()) -> 0.1316208 | AB20: =IFERROR(MATCH($Z20,$B$9:$B$28,0),NA()) -> 11 | AC20: =IFERROR(VLOOKUP($Z20,$J$8:$K$28,2,FALSE),NA()) -> 0.33276253 | AD20: =IFERROR(MATCH($Z20,$J$9:$J$28,0),NA()) -> 2 | AE20: =IFERROR(VLOOKUP($Z20,$R$8:$S$28,2,FALSE),NA()) -> #N/A | AF20: =IFERROR(MATCH($Z20,$R$9:$R$28,0),NA()) -> #N/A | AG20: =AVERAGE(AF20,AD20,AB20) -> #N/A
A21: 14 | B21: moral | C21: 0.10767296 | D21: 0.95 | E21: 0.05900179 | F21: 0.15706503 | G21: 0.10767296 | I21: 14 | J21: affiliation | K21: -0.1071933 | L21: 0.95 | M21: -0.17325584 | N21: -0.04126131 | O21: 0.1071933 | Q21: 14 | R21: tone_neg | S21: -0.081345928 | T21: 0.95 | U21: -0.14440695 | V21: -0.01802884 | W21: 0.081345928 | Z21: ipron | AA21: =IFERROR(VLOOKUP($Z21,$B$8:$C$28,2,FALSE),NA()) -> -0.07770866 | AB21: =IFERROR(MATCH($Z21,$B$9:$B$28,0),NA()) -> 15 | AC21: =IFERROR(VLOOKUP($Z21,$J$8:$K$28,2,FALSE),NA()) -> #N/A | AD21: =IFERROR(MATCH($Z21,$J$9:$J$28,0),NA()) -> #N/A | AE21: =IFERROR(VLOOKUP($Z21,$R$8:$S$28,2,FALSE),NA()) -> 0.062212595 | AF21: =IFERROR(MATCH($Z21,$R$9:$R$28,0),NA()) -> 15 | AG21: =AVERAGE(AF21,AD21,AB21) -> #N/A
A22: 15 | B22: Clout | C22: 0.0893056 | D22: 0.95 | E22: 0.01339805 | F22: 0.1654879 | G22: 0.0893056 | I22: 15 | J22: quantity | K22: 0.1008328 | L22: 0.95 | M22: 0.055523224 | N22: 0.14654283 | O22: 0.1008328 | Q22: 15 | R22: prosocial | S22: 0.069417091 | T22: 0.95 | U22: 0.00342663 | V22: 0.13586949 | W22: 0.069417091 | Z22: comm | AA22: =IFERROR(VLOOKUP($Z22,$B$8:$C$28,2,FALSE),NA()) -> -0.04919621 | AB22: =IFERROR(MATCH($Z22,$B$9:$B$28,0),NA()) -> 16 | AC22: =IFERROR(VLOOKUP($Z22,$J$8:$K$28,2,FALSE),NA()) -> #N/A | AD22: =IFERROR(MATCH($Z22,$J$9:$J$28,0),NA()) -> #N/A | AE22: =IFERROR(VLOOKUP($Z22,$R$8:$S$28,2,FALSE),NA()) -> #N/A | AF22: =IFERROR(MATCH($Z22,$R$9:$R$28,0),NA()) -> #N/A | AG22: =AVERAGE(AF22,AD22,AB22) -> #N/A
A23: 16 | B23: ipron | C23: -0.07770866 | D23: 0.95 | E23: -0.12253855 | F23: -0.032862939 | G23: 0.07770866 | I23: 16 | J23: tone_neg | K23: -0.090600478 | L23: 0.95 | M23: -0.16594807 | N23: -0.01529853 | O23: 0.090600478 | Q23: 16 | R23: ipron | S23: 0.062212595 | T23: 0.95 | U23: 0.011691565 | V23: 0.11293836 | W23: 0.062212595 | Z23: tentat | AA23: =IFERROR(VLOOKUP($Z23,$B$8:$C$28,2,FALSE),NA()) -> -0.03990873 | AB23: =IFERROR(MATCH($Z23,$B$9:$B$28,0),NA()) -> 17 | AC23: =IFERROR(VLOOKUP($Z23,$J$8:$K$28,2,FALSE),NA()) -> #N/A | AD23: =IFERROR(MATCH($Z23,$J$9:$J$28,0),NA()) -> #N/A | AE23: =IFERROR(VLOOKUP($Z23,$R$8:$S$28,2,FALSE),NA()) -> #N/A | AF23: =IFERROR(MATCH($Z23,$R$9:$R$28,0),NA()) -> #N/A | AG23: =AVERAGE(AF23,AD23,AB23) -> #N/A
A24: 17 | B24: comm | C24: -0.04919621 | D24: 0.95 | E24: -0.09345152 | F24: -0.004756028 | G24: 0.04919621 | I24: 17 | J24: discrep | K24: -0.04557006 | L24: 0.95 | M24: -0.094127673 | N24: 0.00298326 | O24: 0.04557006 | Q24: 17 | R24: LSM | S24: 0.043409403 | T24: 0.95 | U24: -0.003003277 | V24: 0.08983444 | W24: 0.043409403 | Z24: LSM | AA24: =IFERROR(VLOOKUP($Z24,$B$8:$C$28,2,FALSE),NA()) -> -0.01142801 | AB24: =IFERROR(MATCH($Z24,$B$9:$B$28,0),NA()) -> 20 | AC24: =IFERROR(VLOOKUP($Z24,$J$8:$K$28,2,FALSE),NA()) -> #N/A | AD24: =IFERROR(MATCH($Z24,$J$9:$J$28,0),NA()) -> #N/A | AE24: =IFERROR(VLOOKUP($Z24,$R$8:$S$28,2,FALSE),NA()) -> 0.043409403 | AF24: =IFERROR(MATCH($Z24,$R$9:$R$28,0),NA()) -> 16 | AG24: =AVERAGE(AF24,AD24,AB24) -> #N/A
A25: 18 | B25: tentat | C25: -0.03990873 | D25: 0.95 | E25: -0.08908286 | F25: 0.00937087 | G25: 0.03990873 | I25: 18 | J25: power | K25: 0.041216283 | L25: 0.95 | M25: -0.001302141 | N25: 0.08388973 | O25: 0.041216283 | Q25: 18 | R25: power | S25: 0.030318544 | T25: 0.95 | U25: -0.018124037 | V25: 0.07909892 | W25: 0.030318544 | Z25: Authentic | AA25: =IFERROR(VLOOKUP($Z25,$B$8:$C$28,2,FALSE),NA()) -> #N/A | AB25: =IFERROR(MATCH($Z25,$B$9:$B$28,0),NA()) -> #N/A | AC25: =IFERROR(VLOOKUP($Z25,$J$8:$K$28,2,FALSE),NA()) -> -0.12089198 | AD25: =IFERROR(MATCH($Z25,$J$9:$J$28,0),NA()) -> 12 | AE25: =IFERROR(VLOOKUP($Z25,$R$8:$S$28,2,FALSE),NA()) -> #N/A | AF25: =IFERROR(MATCH($Z25,$R$9:$R$28,0),NA()) -> #N/A | AG25: =AVERAGE(AF25,AD25,AB25) -> #N/A
... A28: 21 | B28: LSM | C28: -0.01142801 | D28: 0.95 | E28: -0.05861477 | F28: 0.035759235 | G28: 0.01142801 | I28: 21 | J28: they | K28: -0.008754096 | L28: 0.95 | M28: -0.050249237 | N28: 0.03283374 | O28: 0.008754096 | Q28: 21 | R28: reward | S28: 0.009644054 | T28: 0.95 | U28: -0.038024402 | V28: 0.05841393 | W28: 0.009644054 | Z28: insight | AA28: =IFERROR(VLOOKUP($Z28,$B$8:$C$28,2,FALSE),NA()) -> #N/A | AB28: =IFERROR(MATCH($Z28,$B$9:$B$28,0),NA()) -> #N/A | AC28: =IFERROR(VLOOKUP($Z28,$J$8:$K$28,2,FALSE),NA()) -> -0.031574429 | AD28: =IFERROR(MATCH($Z28,$J$9:$J$28,0),NA()) -> 18 | AE28: =IFERROR(VLOOKUP($Z28,$R$8:$S$28,2,FALSE),NA()) -> 0.20976486 | AF28: =IFERROR(MATCH($Z28,$R$9:$R$28,0),NA()) -> 4 | AG28: =AVERAGE(AF28,AD28,AB28) -> #N/A
A29: Showing 1 to 21 of 21 entries, 6 total columns | I29: Showing 1 to 21 of 21 entries, 6 total columns | Q29: Showing 1 to 21 of 21 entries, 6 total columns | Z29: they | AA29: =IFERROR(VLOOKUP($Z29,$B$8:$C$28,2,FALSE),NA()) -> #N/A | AB29: =IFERROR(MATCH($Z29,$B$9:$B$28,0),NA()) -> #N/A | AC29: =IFERROR(VLOOKUP($Z29,$J$8:$K$28,2,FALSE),NA()) -> -0.008754096 | AD29: =IFERROR(MATCH($Z29,$J$9:$J$28,0),NA()) -> 20 | AE29: =IFERROR(VLOOKUP($Z29,$R$8:$S$28,2,FALSE),NA()) -> 0.028875996 | AF29: =IFERROR(MATCH($Z29,$R$9:$R$28,0),NA()) -> 18 | AG29: =AVERAGE(AF29,AD29,AB29) -> #N/A
Z30: allure | AA30: =IFERROR(VLOOKUP($Z30,$B$8:$C$28,2,FALSE),NA()) -> #N/A | AB30: =IFERROR(MATCH($Z30,$B$9:$B$28,0),NA()) -> #N/A | AC30: =IFERROR(VLOOKUP($Z30,$J$8:$K$28,2,FALSE),NA()) -> #N/A | AD30: =IFERROR(MATCH($Z30,$J$9:$J$28,0),NA()) -> #N/A | AE30: =IFERROR(VLOOKUP($Z30,$R$8:$S$28,2,FALSE),NA()) -> -0.11643369 | AF30: =IFERROR(MATCH($Z30,$R$9:$R$28,0),NA()) -> 11 | AG30: =AVERAGE(AF30,AD30,AB30) -> #N/A
Z31: reward | AA31: =IFERROR(VLOOKUP($Z31,$B$8:$C$28,2,FALSE),NA()) -> #N/A | AB31: =IFERROR(MATCH($Z31,$B$9:$B$28,0),NA()) -> #N/A | AC31: =IFERROR(VLOOKUP($Z31,$J$8:$K$28,2,FALSE),NA()) -> #N/A | AD31: =IFERROR(MATCH($Z31,$J$9:$J$28,0),NA()) -> #N/A | AE31: =IFERROR(VLOOKUP($Z31,$R$8:$S$28,2,FALSE),NA()) -> 0.009644054 | AF31: =IFERROR(MATCH($Z31,$R$9:$R$28,0),NA()) -> 20 | AG31: =AVERAGE(AF31,AD31,AB31) -> #N/A
A34: ROUND 2 - OVERLAPPING VARIABLES FROM ROUND 1, minus tone_neg
A35: Claude | I35: GPT-4o | Q35: Deepseek-r1
A36: AUC | B36: 0.7016 | C36: =B36-B4 -> -0.016 | I36: AUC | J36: 0.6741 | K36: =J36-J4 -> -0.0342 | Q36: AUC | R36: 0.6807 | S36: =R36-R4 -> -0.0096 | AA36: RANK | AF36: Std Coefficient
AA37: claude | AB37: GPT-4o | AC37: Deepseek-r1 | AD37: avg | AE37: avg rank | AF37: claude | AG37: GPT-4o
A38: Rank | B38: Parameter | C38: Std_Coefficient | D38: CI | E38: CI_low | F38: CI_high | G38: abs_coef | I38: Rank | J38: Parameter | K38: Std_Coefficient | L38: CI | M38: CI_low | N38: CI_high | O38: abs_coef | Q38: Rank | R38: Parameter | S38: Std_Coefficient | T38: CI | U38: CI_low | V38: CI_high | W38: abs_coef | Z38: assent | AA38: =MATCH($Z38,B$41:B$48,0) -> 1 | AB38: =MATCH($Z38,J$41:J$48,0) -> 1 | AC38: =MATCH($Z38,R$41:R$48,0) -> 7 | AD38: =AVERAGE(AA38:AC38) -> 3 | AE38: 2 | AF38: =VLOOKUP($Z38,$B$41:$C$48,2,FALSE) -> -0.54112154 | AG38: =VLOOKUP($Z38,$J$41:$K$48,2,FALSE) -> -0.3595732
Z39: we | AA39: =MATCH($Z39,B$41:B$48,0) -> 2 | AB39: =MATCH($Z39,J$41:J$48,0) -> 3 | AC39: =MATCH($Z39,R$41:R$48,0) -> 2 | AD39: =AVERAGE(AA39:AC39) -> 2.3333333 | AE39: 1 | AF39: =VLOOKUP($Z39,$B$41:$C$48,2,FALSE) -> 0.42296835 | AG39: =VLOOKUP($Z39,$J$41:$K$48,2,FALSE) -> 0.2390381
A40: 1 | B40: (Intercept) | C40: 0.96640797 | D40: 0.95 | E40: 0.92374469 | F40: 1.0094178 | G40: 0.96640797 | I40: 1 | J40: (Intercept) | K40: 0.4899303 | L40: 0.95 | M40: 0.45136598 | N40: 0.5286397 | O40: 0.4899303 | Q40: 1 | R40: (Intercept) | S40: 1.1855099 | T40: 0.95 | U40: 1.1411045 | V40: 1.2303767 | W40: 1.1855099 | Z40: negate | AA40: =MATCH($Z40,B$41:B$48,0) -> 3 | AB40: =MATCH($Z40,J$41:J$48,0) -> 5 | AC40: =MATCH($Z40,R$41:R$48,0) -> 3 | AD40: =AVERAGE(AA40:AC40) -> 3.6666667 | AE40: 3 | AF40: =VLOOKUP($Z40,$B$41:$C$48,2,FALSE) -> 0.18532498 | AG40: =VLOOKUP($Z40,$J$41:$K$48,2,FALSE) -> 0.1949558
A41: 2 | B41: assent | C41: -0.54112154 | D41: 0.95 | E41: -0.58311834 | F41: -0.49958619 | G41: 0.54112154 | I41: 2 | J41: assent | K41: -0.3595732 | L41: 0.95 | M41: -0.39846106 | N41: -0.3209505 | O41: 0.3595732 | Q41: 2 | R41: moral | S41: 0.3511449 | T41: 0.95 | U41: 0.2986697 | V41: 0.4045709 | W41: 0.3511449 | Z41: risk | AA41: =MATCH($Z41,B$41:B$48,0) -> 4 | AB41: =MATCH($Z41,J$41:J$48,0) -> 4 | AC41: =MATCH($Z41,R$41:R$48,0) -> 4 | AD41: =AVERAGE(AA41:AC41) -> 4 | AE41: 4 | AF41: =VLOOKUP($Z41,$B$41:$C$48,2,FALSE) -> -0.1841094 | AG41: =VLOOKUP($Z41,$J$41:$K$48,2,FALSE) -> -0.2086958
A42: 3 | B42: we | C42: 0.42296835 | D42: 0.95 | E42: 0.36915414 | F42: 0.47791958 | G42: 0.42296835 | I42: 3 | J42: Clout | K42: -0.3170371 | L42: 0.95 | M42: -0.36331724 | N42: -0.2708971 | O42: 0.3170371 | Q42: 3 | R42: we | S42: 0.3175085 | T42: 0.95 | U42: 0.2592369 | V42: 0.3774337 | W42: 0.3175085 | Z42: adj | AA42: =MATCH($Z42,B$41:B$48,0) -> 5 | AB42: =MATCH($Z42,J$41:J$48,0) -> 6 | AC42: =MATCH($Z42,R$41:R$48,0) -> 5 | AD42: =AVERAGE(AA42:AC42) -> 5.3333333 | AE42: 7 | AF42: =VLOOKUP($Z42,$B$41:$C$48,2,FALSE) -> -0.17884088 | AG42: =VLOOKUP($Z42,$J$41:$K$48,2,FALSE) -> -0.16393
A43: 4 | B43: negate | C43: 0.18532498 | D43: 0.95 | E43: 0.13915262 | F43: 0.23181981 | G43: 0.18532498 | I43: 4 | J43: we | K43: 0.2390381 | L43: 0.95 | M43: 0.19254608 | N43: 0.2869726 | O43: 0.2390381 | Q43: 4 | R43: negate | S43: 0.2213562 | T43: 0.95 | U43: 0.1729357 | V43: 0.270057 | W43: 0.2213562 | Z43: moral | AA43: =MATCH($Z43,B$41:B$48,0) -> 6 | AB43: =MATCH($Z43,J$41:J$48,0) -> 7 | AC43: =MATCH($Z43,R$41:R$48,0) -> 1 | AD43: =AVERAGE(AA43:AC43) -> 4.6666667 | AE43: 5 | AF43: =VLOOKUP($Z43,$B$41:$C$48,2,FALSE) -> 0.15327387 | AG43: =VLOOKUP($Z43,$J$41:$K$48,2,FALSE) -> 0.1353287
A44: 5 | B44: risk | C44: -0.1841094 | D44: 0.95 | E44: -0.2241567 | F44: -0.14410616 | G44: 0.1841094 | I44: 5 | J44: risk | K44: -0.2086958 | L44: 0.95 | M44: -0.2479867 | N44: -0.1696908 | O44: 0.2086958 | Q44: 5 | R44: risk | S44: -0.2112753 | T44: 0.95 | U44: -0.2523272 | V44: -0.1702397 | W44: 0.2112753 | Z44: Clout | AA44: =MATCH($Z44,B$41:B$48,0) -> 7 | AB44: =MATCH($Z44,J$41:J$48,0) -> 2 | AC44: =MATCH($Z44,R$41:R$48,0) -> 6 | AD44: =AVERAGE(AA44:AC44) -> 5 | AE44: 6 | AF44: =VLOOKUP($Z44,$B$41:$C$48,2,FALSE) -> -0.13587879 | AG44: =VLOOKUP($Z44,$J$41:$K$48,2,FALSE) -> -0.3170371
...

Sheet Delta RF
A1: Claude | H1: GPT-4o | O1: Deepseek-r1
A3: OOB estimate of error rate: 34.38% | H3: OOB estimate of error rate: 34.95% | O3: OOB estimate of error rate: 39.94%
A4: Confusion matrix: | H4: Confusion matrix: | O4: Confusion matrix:
A5: 0 1 class.error | H5: 0 1 class.error | O5: 0 1 class.error
A6: 0 2329 764 0.2470094 | H6: 0 2284 870 0.2758402 | O6: 0 1738 848 0.3279196
A7: 1 1199 1417 0.4583333 | H7: 1 1221 1607 0.4317539 | O7: 1 1140 1252 0.4765886
A9: Rank | B9: LIWC_Variable | C9: 0 | D9: 1 | E9: MeanDecreaseAccuracy | F9: MeanDecreaseGini | H9: Rank | I9: LIWC_Variable | J9: 0 | K9: 1 | L9: MeanDecreaseAccuracy | M9: MeanDecreaseGini | O9: Rank | P9: LIWC_Variable | Q9: 0 | R9: 1 | S9: MeanDecreaseAccuracy | T9: MeanDecreaseGini
A11: 1 | B11: assent_diff | C11: 18.322188 | D11: 24.624415 | E11: 27.178803 | F11: 114.01224 | H11: 1 | I11: we_diff | J11: 10.083076 | K11: 12.101991 | L11: 15.597336 | M11: 71.775678 | O11: 1 | P11: we_diff | Q11: 20.057802 | R11: 16.811464 | S11: 22.876945 | T11: 87.805304
A12: 2 | B12: we_diff | C12: 17.709509 | D12: 14.704766 | E12: 23.22837 | F12: 105.69066 | H12: 2 | I12: risk_diff | J12: 6.1565936 | K12: 6.7122447 | L12: 8.9755133 | M12: 67.155638 | O12: 2 | P12: assent_diff | Q12: 16.846231 | R12: 18.29154 | S12: 22.370969 | T12: 82.979769
A13: 3 | B13: i_diff | C13: 11.179246 | D13: 5.9430288 | E13: 12.38423 | F13: 74.044684 | H13: 3 | I13: assent_diff | J13: 3.6807121 | K13: 4.2345175 | L13: 5.5573429 | M13: 41.768634 | O13: 3 | P13: moral_diff | Q13: 16.249535 | R13: 9.4283958 | S13: 17.752197 | T13: 79.907127
A14: 4 | B14: memory_diff | C14: 6.8121631 | D14: 5.0916467 | E14: 8.1556413 | F14: 21.809074 | H14: 4 | I14: insight_diff | J14: 7.4809164 | K14: -1.7290565 | L14: 4.4792888 | M14: 58.985546 | O14: 4 | P14: risk_diff | Q14: 8.5565753 | R14: 10.162188 | S14: 12.46078 | T14: 74.431956
A15: 5 | B15: friend_diff | C15: 4.1004035 | D15: 6.2259295 | E15: 7.5536554 | F15: 29.638132 | H15: 5 | I15: cause_diff | J15: 4.2677144 | K15: 1.7682868 | L15: 4.1136179 | M15: 57.546317 | O15: 5 | P15: negate_diff | Q15: 11.977668 | R15: 4.6293466 | S15: 11.478891 | T15: 87.875567
A16: 6 | B16: risk_diff | C16: 0.23475086 | D16: 10.405872 | E16: 7.4086633 | F16: 64.990905 | H16: 6 | I16: friend_diff | J16: 1.2745348 | K16: 4.7519835 | L16: 3.9112755 | M16: 25.919525 | O16: 6 | P16: family_diff | Q16: 2.7067522 | R16: 9.1984726 | S16: 8.7659714 | T16: 26.542937
A17: 7 | B17: moral_diff | C17: 5.7537881 | D17: 4.9793195 | E17: 7.3428255 | F17: 53.021549 | H17: 7 | I17: male_diff | J17: 5.7599516 | K17: 0.32728753 | L17: 3.8410856 | M17: 21.725917 | O17: 7 | P17: allnone_diff | Q17: 9.2774228 | R17: -0.19315275 | S17: 7.0272349 | T17: 63.105289
A18: 8 | B18: c_apology_diff | C18: 6.059298 | D18: 4.2774138 | E18: 7.0428901 | F18: 11.652423 | H18: 8 | I18: allnone_diff | J18: 3.9558022 | K18: 1.1018974 | L18: 3.5509519 | M18: 58.562505 | O18: 8 | P18: certitude_diff | Q18: 4.5867589 | R18: 4.5873973 | S18: 6.8108065 | T18: 59.918073
A19: 9 | B19: affiliation_diff | C19: 1.9950955 | D19: 4.4510554 | E19: 5.2416538 | F19: 60.322616 | H19: 9 | I19: want_diff | J19: 3.6319515 | K19: 0.83298865 | L19: 3.4591901 | M19: 13.400931 | O19: 9 | P19: cause_diff | Q19: 6.2256205 | R19: 0.63057279 | S19: 4.7557706 | T19: 78.067769
A20: 10 | B20: polite_diff | C20: 3.3531926 | D20: 3.8318812 | E20: 5.2196242 | F20: 25.471333 | H20: 10 | I20: i_diff | J20: 3.2489022 | K20: 1.5650229 | L20: 3.3766481 | M20: 36.378466 | O20: 10 | P20: emo_anger_diff | Q20: 2.1855997 | R20: 4.7157042 | S20: 4.6463129 | T20: 17.940332
A21: 11 | B21: achieve_diff | C21: 3.929833 | D21: 2.954966 | E21: 5.042115 | F21: 62.253962 | H21: 11 | I21: LSM_diff | J21: 4.0648967 | K21: 0.36420378 | L21: 3.2363794 | M21: 50.626136 | O21: 11 | P21: Tone_diff | Q21: 3.0502725 | R21: 2.4838523 | S21: 4.4907357 | T21: 66.63888
A22: 12 | B22: negate_diff | C22: 7.1476443 | D22: -0.96813269 | E22: 4.6755513 | F22: 64.87882 | H22: 12 | I22: Authentic_diff | J22: 2.7719923 | K22: 1.6868107 | L22: 3.1284029 | M22: 51.342876 | O22: 12 | P22: tone_pos_diff | Q22: 0.39844395 | R22: 5.320897 | S22: 4.34999 | T22: 67.353183
... A71: 61 | B71: Authentic_diff | C71: -0.5082044 | D71: -0.73613501 | E71: -0.9576244 | F71: 55.444003 | H71: 61 | I71: emo_anger_diff | J71: -2.3335169 | K71: -0.96658201 | L71: -2.4485224 | M71: 25.157009 | O71: 61 | P71: netspeak_diff | Q71: -1.7451945 | R71: -1.0773627 | S71: -1.9210363 | T71: 3.1310744
A72: Showing 1 to 21 of 61 entries, 5 total columns | H72: Showing 1 to 21 of 61 entries, 5 total columns | O72: Showing 1 to 21 of 61 entries, 5 total columns

Sheet Delta GLM
A1: Claude | I1: GPT-4o | Q1: Deepseek-r1
A2: AUC | B2: 0.5743 | I2: AUC | J2: 0.5614 | Q2: AUC | R2: 0.5614
B4: Parameter | C4: Std_Coefficient | D4: CI | E4: CI_low | F4: CI_high | G4: abs_coef | J4: Parameter | K4: Std_Coefficient | L4: CI | M4: CI_low | N4: CI_high | O4: abs_coef | R4: Parameter | S4: Std_Coefficient | T4: CI | U4: CI_low | V4: CI_high | W4: abs_coef
A6: 1 | B6: (Intercept) | C6: 0.74436892 | D6: 0.95 | E6: 0.70134208 | F6: 0.78762702 | G6: 0.74436892 | I6: 1 | J6: (Intercept) | K6: 0.35992959 | L6: 0.95 | M6: 0.31874374 | N6: 0.40122 | O6: 0.35992959 | Q6: 1 | R6: (Intercept) | S6: 1.0276916 | T6: 0.95 | U6: 0.98258523 | V6: 1.0731378 | W6: 1.0276916
A7: 2 | B7: i_diff | C7: -0.19817315 | D7: 0.95 | E7: -0.24492853 | F7: -0.15198491 | G7: 0.19817315 | I7: 2 | J7: LSM_diff | K7: 0.12403665 | L7: 0.95 | M7: 0.081618447 | N7: 0.1665607 | O7: 0.12403665 | Q7: 2 | R7: i_diff | S7: -0.12638501 | T7: 0.95 | U7: -0.18083185 | V7: -0.073507917 | W7: 0.12638501
A8: 3 | B8: friend_diff | C8: 0.098055462 | D8: 0.95 | E8: 0.049936747 | F8: 0.14630422 | G8: 0.098055462 | I8: 3 | J8: risk_diff | K8: 0.095017856 | L8: 0.95 | M8: 0.053172621 | N8: 0.1371273 | O8: 0.095017856 | Q8: 3 | R8: risk_diff | S8: 0.10562399 | T8: 0.95 | U8: 0.060891097 | V8: 0.15034745 | W8: 0.10562399
A9: 4 | B9: achieve_diff | C9: -0.078279978 | D9: 0.95 | E9: -0.12503253 | F9: -0.03163259 | G9: 0.078279978 | I9: 4 | J9: assent_diff | K9: -0.088485197 | L9: 0.95 | M9: -0.13436804 | N9: -0.042740728 | O9: 0.088485197 | Q9: 4 | R9: insight_diff | S9: -0.10299036 | T9: 0.95 | U9: -0.15370938 | V9: -0.052352756 | W9: 0.10299036
A10: 5 | B10: affiliation_diff | C10: -0.067953714 | D10: 0.95 | E10: -0.13001841 | F10: -0.006126749 | G10: 0.067953714 | I10: 5 | J10: need_diff | K10: 0.083179041 | L10: 0.95 | M10: 0.041359291 | N10: 0.12509652 | O10: 0.083179041 | Q10: 5 | R10: affiliation_diff | S10: -0.0947145 | T10: 0.95 | U10: -0.15124426 | V10: -0.038580822 | W10: 0.0947145
A11: 6 | B11: we_diff | C11: 0.06794154 | D11: 0.95 | E11: 0.010465988 | F11: 0.12553113 | G11: 0.06794154 | I11: 6 | J11: female_diff | K11: 0.051632652 | L11: 0.95 | M11: 0.009644216 | N11: 0.093853389 | O11: 0.051632652 | Q11: 6 | R11: we_diff | S11: 0.080587269 | T11: 0.95 | U11: 0.024307748 | V11: 0.1369866 | W11: 0.080587269
A12: 7 | B12: risk_diff | C12: 0.063576577 | D12: 0.95 | E12: 0.02007621 | F12: 0.10713802 | G12: 0.063576577 | I12: 7 | J12: cause_diff | K12: -0.04155777 | L12: 0.95 | M12: -0.083447359 | N12: 0.0002962828 | O12: 0.04155777 | Q12: 7 | R12: curiosity_diff | S12: -0.072987446 | T12: 0.95 | U12: -0.11896195 | V12: -0.027144735 | W12: 0.072987446
A13: 8 | B13: conflict_diff | C13: 0.059166035 | D13: 0.95 | E13: 0.014515486 | F13: 0.10396182 | G13: 0.059166035 | I13: 8 | J13: you_diff | K13: 0.039118142 | L13: 0.95 | M13: -0.003534333 | N13: 0.081993136 | O13: 0.039118142 | Q13: 8 | R13: Clout_diff | S13: -0.059457395 | T13: 0.95 | U13: -0.13282811 | V13: 0.013842831 | W13: 0.059457395
A14: 9 | B14: female_diff | C14: 0.058302192 | D14: 0.95 | E14: 0.014942387 | F14: 0.10144894 | G14: 0.058302192 | I14: 9 | J14: adverb_diff | K14: 0.034541422 | L14: 0.95 | M14: -0.009313417 | N14: 0.078428833 | O14: 0.034541422 | Q14: 9 | R14: verb_diff | S14: 0.059123455 | T14: 0.95 | U14: 0.008302423 | V14: 0.11000862 | W14: 0.059123455
A15: 10 | B15: assent_diff | C15: -0.042813212 | D15: 0.95 | E15: -0.08777045 | F15: 0.002201145 | G15: 0.042813212 | I15: 10 | J15: Tone_diff | K15: 0.031571723 | L15: 0.95 | M15: -0.035934415 | N15: 0.099133038 | O15: 0.031571723 | Q15: 10 | R15: negate_diff | S15: -0.055262806 | T15: 0.95 | U15: -0.11189214 | V15: 0.001316594 | W15: 0.055262806
A16: 11 | B16: c_apology_diff | C16: -0.037903652 | D16: 0.95 | E16: -0.083763023 | F16: 0.007796042 | G16: 0.037903652 | I16: 11 | J16: certitude_diff | K16: 0.024667413 | L16: 0.95 | M16: -0.018592229 | N16: 0.067969676 | O16: 0.024667413 | Q16: 11 | R16: friend_diff | S16: 0.053675014 | T16: 0.95 | U16: 0.00373324 | V16: 0.10377175 | W16: 0.053675014
A17: 12 | B17: emo_anx_diff | C17: 0.03751469 | D17: 0.95 | E17: -0.006869502 | F17: 0.082098122 | G17: 0.03751469 | I17: 12 | J17: we_diff | K17: -0.024019739 | L17: 0.95 | M17: -0.065654996 | N17: 0.017341824 | O17: 0.024019739 | Q17: 12 | R17: male_diff | S17: -0.034694694 | T17: 0.95 | U17: -0.082371398 | V17: 0.012399829 | W17: 0.034694694
... A26: 21 | B26: memory_diff | C26: -0.00181038 | D26: 0.95 | E26: -0.044976516 | F26: 0.041397752 | G26: 0.00181038 | I26: 21 | J26: tone_pos_diff | K26: -0.0003559202 | L26: 0.95 | M26: -0.068437467 | N26: 0.067659137 | O26: 0.0003559202 | Q26: 21 | R26: cause_diff | S26: -0.001573977 | T26: 0.95 | U26: -0.047320832 | V26: 0.044143761 | W26: 0.001573977
A27: Showing 1 to 21 of 21 entries, 6 total columns | I27: Showing 1 to 21 of 21 entries, 6 total columns | Q27: Showing 1 to 21 of 21 entries, 6 total columns

Sheet Combined RF
A1: Claude | H1: GPT-4o | O1: Deepseek-r1
A3: OOB estimate of error rate: 27.05% | H3: OOB estimate of error rate: 24.62% | O3: OOB estimate of error rate: 31.13%
A4: Confusion matrix: | H4: Confusion matrix: | O4: Confusion matrix:
A5: 0 1 class.error | H5: 0 1 class.error | O5: 0 1 class.error
A6: 0 2475 618 0.1998060 | H6: 0 2512 640 0.2030457 | O6: 0 1915 671 0.2594741
A7: 1 926 1690 0.3539755 | H7: 1 835 2003 0.2942213 | O7: 1 878 1512 0.3673640
A9: Rank | B9: LIWC_Variable | C9: 0 | D9: 1 | E9: MeanDecreaseAccuracy | F9: MeanDecreaseGini | H9: Rank | I9: LIWC_Variable | J9: 0 | K9: 1 | L9: MeanDecreaseAccuracy | M9: MeanDecreaseGini | O9: Rank | P9: LIWC_Variable | Q9: 0 | R9: 1 | S9: MeanDecreaseAccuracy | T9: MeanDecreaseGini
A11: 1 | B11: we | C11: 18.593796 | D11: 16.859302 | E11: 25.095339 | F11: 69.248731 | H11: 1 | I11: moral | J11: 14.315034 | K11: 29.025494 | L11: 31.707288 | M11: 85.998867 | O11: 1 | P11: risk | Q11: 16.669233 | R11: 13.082534 | S11: 20.369908 | T11: 50.727069
A12: 2 | B12: assent | C12: 19.411692 | D12: 18.568944 | E12: 24.433329 | F12: 62.304691 | H12: 2 | I12: negate | J12: 19.517571 | K12: 25.096362 | L12: 29.563134 | M12: 91.022077 | O12: 2 | P12: negate | Q12: 15.65635 | R12: 11.469229 | S12: 19.794529 | T12: 66.221124
A13: 3 | B13: negate | C13: 17.403506 | D13: 18.51826 | E13: 24.402822 | F13: 72.486408 | H13: 3 | I13: cause | J13: 18.136799 | K13: 17.86653 | L13: 23.634241 | M13: 83.127402 | O13: 3 | P13: we | Q13: 10.27425 | R13: 15.749485 | S13: 18.666129 | T13: 45.561716
A14: 4 | B14: assent_diff | C14: 13.643635 | D14: 18.424769 | E14: 20.392886 | F14: 57.640054 | H14: 4 | I14: risk | J14: 17.440064 | K14: 19.087267 | L14: 22.025398 | M14: 56.465923 | O14: 4 | P14: moral | Q14: 6.4654432 | R14: 14.813226 | S14: 15.797947 | T14: 30.773934
A15: 5 | B15: risk | C15: 14.646946 | D15: 15.704636 | E15: 19.308613 | F15: 42.953085 | H15: 5 | I15: assent | J15: 13.569879 | K15: 18.675419 | L15: 20.902071 | M15: 44.309239 | O15: 5 | P15: insight | Q15: 6.7461389 | R15: 11.073425 | S15: 13.324717 | T15: 38.635998
A16: 6 | B16: Tone | C16: 11.436101 | D16: 11.249975 | E16: 16.198311 | F16: 45.211645 | H16: 6 | I16: insight | J16: 5.6269078 | K16: 20.03209 | L16: 20.110672 | M16: 52.113487 | O16: 6 | P16: LSM | Q16: 9.7741034 | R16: 6.5353565 | S16: 12.692501 | T16: 39.156388
A17: 7 | B17: differ | C17: 12.008165 | D17: 10.944535 | E17: 15.655358 | F17: 51.288884 | H17: 7 | I17: adj | J17: 11.71884 | K17: 16.172329 | L17: 20.060304 | M17: 55.009076 | O17: 7 | P17: ipron | Q17: 8.2437212 | R17: 8.5155579 | S17: 11.276801 | T17: 39.954456
A18: 8 | B18: tone_pos | C18: 10.605605 | D18: 12.593205 | E18: 15.629586 | F18: 46.335535 | H18: 8 | I18: differ | J18: 15.452943 | K18: 12.045084 | L18: 19.370684 | M18: 59.290466 | O18: 8 | P18: affiliation | Q18: 0.007521564 | R18: 12.13699 | S18: 10.884443 | T18: 25.651304
A19: 9 | B19: moral | C19: 9.0931204 | D19: 13.728147 | E19: 15.280395 | F19: 33.056208 | H19: 9 | I19: we | J19: 17.068397 | K19: 13.665243 | L19: 18.862758 | M19: 41.34238 | O19: 9 | P19: adj | Q19: 9.2962483 | R19: 5.4341853 | S19: 10.52582 | T19: 45.303659
A20: 10 | B20: affiliation | C20: 5.1483163 | D20: 14.10247 | E20: 14.744715 | F20: 38.034598 | H20: 10 | I20: Clout | J20: 5.3193945 | K20: 16.759779 | L20: 17.114846 | M20: 48.266129 | O20: 10 | P20: differ | Q20: 8.9824167 | R20: 4.4725876 | S20: 9.9138987 | T20: 33.057088
A21: 11 | B21: adj | C21: 11.74113 | D21: 6.5036306 | E21: 13.344826 | F21: 47.233459 | H21: 11 | I21: quantity | J21: 12.017665 | K21: 14.456211 | L21: 17.0524 | M21: 55.478111 | O21: 11 | P21: auxverb | Q21: 5.9815802 | R21: 5.7146682 | S21: 9.3280994 | T21: 34.979417
A22: 12 | B22: we_diff | C22: 11.677747 | D22: 6.4298014 | E22: 13.051827 | F22: 40.197589 | H22: 12 | I22: Tone | J22: 11.239702 | K22: 8.059331 | L22: 15.015039 | M22: 39.254731 | O22: 12 | P22: power | Q22: 7.9144458 | R22: 3.497269 | S22: 8.6716835 | T22: 33.192873
... A132: 122 | B132: discrep_diff | C132: -0.67799227 | D132: -0.80629142 | E132: -1.0846171 | F132: 28.299919 | H132: 122 | I132: c_apology | J132: -1.0010015 | K132: -1.4165301 | L132: -1.737226 | M132: 0.22182237 | O132: 122 | P132: nonflu_diff | Q132: -0.56368065 | R132: -2.2978108 | S132: -1.8820854 | T132: 1.0250949
A133: Showing 1 to 15 of 122 entries, 5 total columns | H133: Showing 1 to 15 of 122 entries, 5 total columns | O133: Showing 1 to 15 of 122 entries, 5 total columns

Sheet Combined GLM
A1: ROUND 1 - TOP 20 VARIABLES MINUS HIGHLY CORRELATED ONES
A2: Claude | I2: GPT-4o | Q2: Deepseek-r1
A3: Correlations | I3: Correlations | J3: Tone, tone_pos | O3: ` | Q3: Correlations
A4: AUC | B4: 0.7487 | I4: AUC | J4: 0.7345 | Q4: AUC | R4: 0.6972 | Z4: claude | AA4: GPT-4o | AB4: Deepseek-r1
A5: State AUC | B5: 0.7176 | I5: State AUC | J5: 0.7083 | Q5: State AUC | R5: 0.6903 | Y5: assent | Z5: =MATCH($Y5,B$9:B$22,0) -> 1 | AA5: =MATCH($Y5,J$9:J$26,0) -> 1 | AB5: =MATCH($Y5,R$8:R$23,0) -> 4
Y6: assent_diff | Z6: =MATCH($Y6,B$9:B$22,0) -> 3 | AA6: =MATCH($Y6,J$9:J$26,0) -> 5 | AB6: =MATCH($Y6,R$8:R$23,0) -> 11
A7: Rank | B7: Parameter | C7: Std_Coefficient | D7: CI | E7: CI_low | F7: CI_high | G7: abs_coef | I7: Rank | J7: Parameter | K7: Std_Coefficient | L7: CI | M7: CI_low | N7: CI_high | O7: abs_coef | Q7: Rank | R7: Parameter | S7: Std_Coefficient | T7: CI | U7: CI_low | V7: CI_high | W7: abs_coef | Y7: we | Z7: =MATCH($Y7,B$9:B$22,0) -> 4 | AA7: =MATCH($Y7,J$9:J$26,0) -> 6 | AB7: =MATCH($Y7,R$8:R$23,0) -> 3
Y8: negate | Z8: =MATCH($Y8,B$9:B$22,0) -> 5 | AA8: =MATCH($Y8,J$9:J$26,0) -> 8 | AB8: =MATCH($Y8,R$8:R$23,0) -> 9
A9: 1 | B9: assent | C9: -0.86459742 | D9: 0.95 | E9: -0.93085215 | F9: -0.79925466 | G9: 0.86459742 | I9: 1 | J9: assent | K9: -0.64462125 | L9: 0.95 | M9: -0.70321545 | N9: -0.5865569 | O9: 0.64462125 | Q9: 1 | R9: (Intercept) | S9: 1.143888 | T9: 0.95 | U9: 1.0941512 | V9: 1.1942067 | W9: 1.143888 | Y9: adj | Z9: =MATCH($Y9,B$9:B$22,0) -> 6 | AA9: =MATCH($Y9,J$9:J$26,0) -> 12 | AB9: =MATCH($Y9,R$8:R$23,0) -> 5
A10: 2 | B10: (Intercept) | C10: 0.86162557 | D10: 0.95 | E10: 0.81338139 | F10: 0.91028555 | G10: 0.86162557 | I10: 2 | J10: (Intercept) | K10: 0.42994987 | L10: 0.95 | M10: 0.38544611 | N10: 0.47463019 | O10: 0.42994987 | Q10: 2 | R10: we | S10: 0.37481999 | T10: 0.95 | U10: 0.3041231 | V10: 0.44710058 | W10: 0.37481999 | Y10: risk | Z10: =MATCH($Y10,B$9:B$22,0) -> 7 | AA10: =MATCH($Y10,J$9:J$26,0) -> 13 | AB10: =MATCH($Y10,R$8:R$23,0) -> 7
A11: 3 | B11: assent_diff | C11: 0.52873015 | D11: 0.95 | E11: 0.46978414 | F11: 0.58826608 | G11: 0.52873015 | I11: 3 | J11: Tone | K11: 0.38164268 | L11: 0.95 | M11: 0.21792946 | N11: 0.54623157 | O11: 0.38164268 | Q11: 3 | R11: assent | S11: -0.30407186 | T11: 0.95 | U11: -0.36590444 | V11: -0.24219523 | W11: 0.30407186 | Y11: you | Z11: =MATCH($Y11,B$9:B$22,0) -> 8 | AA11: =MATCH($Y11,J$9:J$26,0) -> #N/A | AB11: =MATCH($Y11,R$8:R$23,0) -> #N/A
A12: 4 | B12: we | C12: 0.47673758 | D12: 0.95 | E12: 0.4000656 | F12: 0.55448198 | G12: 0.47673758 | I12: 4 | J12: cause | K12: 0.35790679 | L12: 0.95 | M12: 0.30825312 | N12: 0.40794987 | O12: 0.35790679 | Q12: 4 | R12: adj | S12: -0.27906538 | T12: 0.95 | U12: -0.32842654 | V12: -0.22988028 | W12: 0.27906538 | Y12: cause | Z12: =MATCH($Y12,B$9:B$22,0) -> 9 | AA12: =MATCH($Y12,J$9:J$26,0) -> 4 | AB12: =MATCH($Y12,R$8:R$23,0) -> #N/A
A13: 5 | B13: negate | C13: 0.25602455 | D13: 0.95 | E13: 0.20100451 | F13: 0.31144783 | G13: 0.25602455 | I13: 5 | J13: assent_diff | K13: 0.30849241 | L13: 0.95 | M13: 0.25392402 | N13: 0.36327208 | O13: 0.30849241 | Q13: 5 | R13: moral | S13: 0.2638726 | T13: 0.95 | U13: 0.20016635 | V13: 0.32865193 | W13: 0.2638726 | Y13: we_diff | Z13: =MATCH($Y13,B$9:B$22,0) -> 10 | AA13: =MATCH($Y13,J$9:J$26,0) -> 18 | AB13: =MATCH($Y13,R$8:R$23,0) -> #N/A
A14: 6 | B14: adj | C14: -0.21291605 | D14: 0.95 | E14: -0.26395558 | F14: -0.16200933 | G14: 0.21291605 | I14: 6 | J14: we | K14: 0.27420113 | L14: 0.95 | M14: 0.21851414 | N14: 0.33140809 | O14: 0.27420113 | Q14: 6 | R14: risk | S14: -0.17420444 | T14: 0.95 | U14: -0.22175094 | V14: -0.12663312 | W14: 0.17420444 | Y14: i_diff | Z14: =MATCH($Y14,B$9:B$22,0) -> 11 | AA14: =MATCH($Y14,J$9:J$26,0) -> #N/A | AB14: =MATCH($Y14,R$8:R$23,0) -> #N/A
A15: 7 | B15: risk | C15: -0.20850738 | D15: 0.95 | E15: -0.25738082 | F15: -0.15982814 | G15: 0.20850738 | I15: 7 | J15: Clout | K15: -0.26314043 | L15: 0.95 | M15: -0.33044316 | N15: -0.19592692 | O15: 0.26314043 | Q15: 7 | R15: Clout | S15: -0.16802027 | T15: 0.95 | U15: -0.23464778 | V15: -0.10115285 | W15: 0.16802027 | Y15: differ | Z15: =MATCH($Y15,B$9:B$22,0) -> 12 | AA15: =MATCH($Y15,J$9:J$26,0) -> 11 | AB15: =MATCH($Y15,R$8:R$23,0) -> #N/A
A16: 8 | B16: you | C16: -0.20085621 | D16: 0.95 | E16: -0.2749021 | F16: -0.12696085 | G16: 0.20085621 | I16: 8 | J16: negate | K16: 0.24516863 | L16: 0.95 | M16: 0.1865439 | N16: 0.3042569 | O16: 0.24516863 | Q16: 8 | R16: negate | S16: 0.16759575 | T16: 0.95 | U16: 0.10139428 | V16: 0.23407472 | W16: 0.16759575 | Y16: verb | Z16: =MATCH($Y16,B$9:B$22,0) -> 13 | AA16: =MATCH($Y16,J$9:J$26,0) -> #N/A | AB16: =MATCH($Y16,R$8:R$23,0) -> #N/A
A17: 9 | B17: cause | C17: 0.17383535 | D17: 0.95 | E17: 0.12384861 | F17: 0.2241519 | G17: 0.17383535 | I17: 9 | J17: tone_pos | K17: -0.23440601 | L17: 0.95 | M17: -0.37586399 | N17: -0.09381113 | O17: 0.23440601 | Q17: 9 | R17: allnone | S17: 0.16753575 | T17: 0.95 | U17: 0.11081522 | V17: 0.22494778 | W17: 0.16753575 | Y17: tentat | Z17: =MATCH($Y17,B$9:B$22,0) -> 14 | AA17: =MATCH($Y17,J$9:J$26,0) -> #N/A | AB17: =MATCH($Y17,R$8:R$23,0) -> #N/A
A18: 10 | B18: we_diff | C18: -0.17280825 | D18: 0.95 | E18: -0.23259525 | F18: -0.11409486 | G18: 0.17280825 | I18: 10 | J18: moral | K18: 0.20764853 | L18: 0.95 | M18: 0.15259768 | N18: 0.26329395 | O18: 0.20764853 | Q18: 10 | R18: assent_diff | S18: 0.1435797 | T18: 0.95 | U18: 0.084681943 | V18: 0.20212976 | W18: 0.1435797 | Y18: Tone | Z18: =MATCH($Y18,B$9:B$22,0) -> #N/A | AA18: =MATCH($Y18,J$9:J$26,0) -> 3 | AB18: =MATCH($Y18,R$8:R$23,0) -> 16
A19: 11 | B19: i_diff | C19: -0.14361936 | D19: 0.95 | E19: -0.19356057 | F19: -0.094187 | G19: 0.14361936 | I19: 11 | J19: differ | K19: -0.20290377 | L19: 0.95 | M19: -0.26234321 | N19: -0.14357626 | O19: 0.20290377 | Q19: 11 | R19: insight | S19: 0.14024858 | T19: 0.95 | U19: 0.081423731 | V19: 0.19957963 | W19: 0.14024858 | Y19: Clout | Z19: =MATCH($Y19,B$9:B$22,0) -> #N/A | AA19: =MATCH($Y19,J$9:J$26,0) -> 7 | AB19: =MATCH($Y19,R$8:R$23,0) -> 8
A20: 12 | B20: differ | C20: 0.1383274 | D20: 0.95 | E20: 0.07279812 | F20: 0.2041033 | G20: 0.1383274 | I20: 12 | J20: adj | K20: -0.15702028 | L20: 0.95 | M20: -0.20615132 | N20: -0.10798399 | O20: 0.15702028 | Q20: 12 | R20: quantity | S20: 0.12347326 | T20: 0.95 | U20: 0.068901404 | V20: 0.17871719 | W20: 0.12347326 | Y20: tone_pos | Z20: =MATCH($Y20,B$9:B$22,0) -> #N/A | AA20: =MATCH($Y20,J$9:J$26,0) -> 9 | AB20: =MATCH($Y20,R$8:R$23,0) -> #N/A
... A27: 19 | B27: adverb | C27: 0.03191714 | D27: 0.95 | E27: -0.01995978 | F27: 0.08389763 | G27: 0.03191714 | I27: 19 | J27: tone_neg | K27: -0.028916909 | L27: 0.95 | M27: -0.11820827 | N27: 0.06053209 | O27: 0.028916909 | Q27: 19 | R27: power | S27: 0.03463643 | T27: 0.95 | U27: -0.017586793 | V27: 0.08727123 | W27: 0.03463643 | Y27: ipron | Z27: =MATCH($Y27,B$9:B$22,0) -> #N/A | AA27: =MATCH($Y27,J$9:J$26,0) -> #N/A | AB27: =MATCH($Y27,R$8:R$23,0) -> 15
A28: 20 | B28: power | C28: -0.01913256 | D28: 0.95 | E28: -0.06978764 | F28: 0.03178823 | G28: 0.01913256 | I28: 20 | J28: power | K28: 0.022198217 | L28: 0.95 | M28: -0.02537459 | N28: 0.06991757 | O28: 0.022198217 | Q28: 20 | R28: they | S28: 0.02764507 | T28: 0.95 | U28: -0.023605754 | V28: 0.07942485 | W28: 0.02764507
A29: 21 | B29: affiliation | C29: -0.0148347 | D29: 0.95 | E29: -0.08381737 | F29: 0.05448056 | G29: 0.0148347 | I29: 21 | J29: they | K29: -0.008095306 | L29: 0.95 | M29: -0.05530802 | N29: 0.03913622 | O29: 0.008095306 | Q29: 21 | R29: tentat | S29: 0.01999075 | T29: 0.95 | U29: -0.044119731 | V29: 0.08422245 | W29: 0.01999075
A30: Showing 1 to 15 of 21 entries, 6 total columns | I30: Showing 1 to 15 of 21 entries, 6 total columns | Q30: Showing 1 to 15 of 21 entries, 6 total columns
A33: ROUND 2 - OVERLAPPING VARIABLES FROM ROUND 1
A35: Claude | I35: GPT-4o | Q35: Deepseek-r1
A36: AUC | B36: 0.7326 | I36: AUC | J36: 0.6805 | Q36: AUC | R36: 0.6801
A37: State AUC | B37: ='State GLM'!B103 -> 0.6978 | C37: =B36-B37 -> 0.0348 | I37: State AUC | J37: ='State GLM'!J103 -> 0.6549 | K37: =J36-J37 -> 0.0256 | Q37: State AUC | R37: ='State GLM'!R103 -> 0.658 | S37: =R36-R37 -> 0.0221
B39: Parameter | C39: Std_Coefficient | D39: CI | E39: CI_low | F39: CI_high | G39: abs_coef | J39: Parameter | K39: Std_Coefficient | L39: CI | M39: CI_low | N39: CI_high | O39: abs_coef | R39: Parameter | S39: Std_Coefficient | T39: CI | U39: CI_low | V39: CI_high | W39: abs_coef
A41: 1 | B41: assent | C41: -0.9233057 | D41: 0.95 | E41: -0.9866239 | F41: -0.8609218 | G41: 0.9233057 | I41: 1 | J41: assent | K41: -0.63855298 | L41: 0.95 | M41: -0.693784 | N41: -0.5838316 | O41: 0.63855298 | Q41: 1 | R41: (Intercept) | S41: 1.1178292 | T41: 0.95 | U41: 1.0693575 | V41: 1.1668322 | W41: 1.1178292
A42: 2 | B42: (Intercept) | C42: 0.8387592 | D42: 0.95 | E42: 0.7917026 | F42: 0.8861914 | G42: 0.8387592 | I42: 2 | J42: (Intercept) | K42: 0.39675778 | L42: 0.95 | M42: 0.3544644 | N42: 0.4391911 | O42: 0.39675778 | Q42: 2 | R42: we | S42: 0.3745897 | T42: 0.95 | U42: 0.3124045 | V42: 0.4386386 | W42: 0.3745897
A43: 3 | B43: assent_diff | C43: 0.5426037 | D43: 0.95 | E43: 0.4850281 | F43: 0.600768 | G43: 0.5426037 | I43: 3 | J43: negate | K43: 0.33389044 | L43: 0.95 | M43: 0.2871972 | N43: 0.3810776 | O43: 0.33389044 | Q43: 3 | R43: negate | S43: 0.3263949 | T43: 0.95 | U43: 0.275542 | V43: 0.3776765 | W43: 0.3263949
A44: 4 | B44: we | C44: 0.4498436 | D44: 0.95 | E44: 0.3927614 | F44: 0.50822 | G44: 0.4498436 | I44: 4 | J44: assent_diff | K44: 0.316341 | L44: 0.95 | M44: 0.2640124 | N44: 0.368941 | O44: 0.316341 | Q44: 4 | R44: assent | S44: -0.2818053 | T44: 0.95 | U44: -0.3396508 | V44: -0.2238298 | W44: 0.2818053
A45: 5 | B45: negate | C45: 0.2376667 | D45: 0.95 | E45: 0.1887867 | F45: 0.2869651 | G45: 0.2376667 | I45: 5 | J45: we | K45: 0.21508079 | L45: 0.95 | M45: 0.1660988 | N45: 0.2655713 | O45: 0.21508079 | Q45: 5 | R45: adj | S45: -0.2680748 | T45: 0.95 | U45: -0.3143391 | V45: -0.2219511 | W45: 0.2680748
A46: 6 | B46: risk | C46: -0.1774075 | D46: 0.95 | E46: -0.2218677 | F46: -0.1330994 | G46: 0.1774075 | I46: 6 | J46: risk | K46: -0.19759234 | L46: 0.95 | M46: -0.2410968 | N46: -0.1544221 | O46: 0.19759234 | Q46: 6 | R46: risk | S46: -0.1708653 | T46: 0.95 | U46: -0.2143531 | V46: -0.1273352 | W46: 0.1708653
A47: 7 | B47: adj | C47: -0.1724624 | D47: 0.95 | E47: -0.2195515 | F47: -0.1254872 | G47: 0.1724624 | I47: 7 | J47: adj | K47: -0.05936278 | L47: 0.95 | M47: -0.1024723 | N47: -0.0163378 | O47: 0.05936278 | Q47: 7 | R47: assent_diff | S47: 0.1628085 | T47: 0.95 | U47: 0.105159 | V47: 0.2201279 | W47: 0.1628085
A48: Showing 1 to 7 of 7 entries, 6 total columns | I48: Showing 1 to 7 of 7 entries, 6 total columns | Q48: Showing 1 to 7 of 7 entries, 6 total columns
A51: ROUND 3 - OVERLAPPING VARIABLES FROM STATE GLM + ASSENT DIFF
A53: Claude | I53: GPT-4o | Q53: Deepseek-r1
A54: AUC | B54: 0.7331 | I54: AUC | J54: 0.6988 | Q54: AUC | R54: 0.6899
...

Sheet Validation
A1: STATE ONLY - 8 VARIABLES
A2: Llama-3.3-70B-Instruct | I2: Qwen2.5-72B-Instruct | R2: Claude | S2: GPT-4o | T2: Deepseek-r1
A3: AUC | B3: 0.6945 | I3: AUC | J3: 0.6766 | Q3: AUC | R3: ='State GLM'!B36 -> 0.7016 | S3: ='State GLM'!J36 -> 0.6741 | T3: ='State GLM'!R36 -> 0.6807
B5: Parameter | C5: Std_Coefficient | D5: CI | E5: CI_low | F5: CI_high | G5: abs_coef | J5: Parameter | K5: Std_Coefficient | L5: CI | M5: CI_low | N5: CI_high | O5: abs_coef
A7: 1 | B7: assent | C7: -0.49926382 | D7: 0.95 | E7: -0.54870455 | F7: -0.45086026 | G7: 0.49926382 | I7: 1 | J7: assent | K7: -0.57288767 | L7: 0.95 | M7: -0.61980767 | N7: -0.52685613 | O7: 0.57288767
A8: 2 | B8: Tone | C8: 0.40691532 | D8: 0.95 | E8: 0.36523558 | F8: 0.44880424 | G8: 0.40691532 | I8: 2 | J8: Tone | K8: 0.36791525 | L8: 0.95 | M8: 0.32634526 | N8: 0.40967189 | O8: 0.36791525
A9: 3 | B9: adj | C9: -0.31672978 | D9: 0.95 | E9: -0.35680923 | F9: -0.27685089 | G9: 0.31672978 | I9: 3 | J9: adj | K9: -0.22586426 | L9: 0.95 | M9: -0.26442676 | N9: -0.18743672 | O9: 0.22586426
A10: 4 | B10: we | C10: 0.20268149 | D10: 0.95 | E10: 0.16105771 | F10: 0.24509484 | G10: 0.20268149 | I10: 4 | J10: moral | K10: 0.16565013 | L10: 0.95 | M10: 0.12634434 | N10: 0.20533627 | O10: 0.16565013
A11: 5 | B11: moral | C11: 0.19786975 | D11: 0.95 | E11: 0.15880035 | F11: 0.23724532 | G11: 0.19786975 | I11: 5 | J11: we | K11: 0.13018067 | L11: 0.95 | M11: 0.089411011 | N11: 0.1721193 | O11: 0.13018067
A12: 6 | B12: (Intercept) | C12: -0.115086 | D12: 0.95 | E12: -0.15316196 | F12: -0.0770748 | G12: 0.115086 | I12: 6 | J12: Clout | K12: -0.11435142 | L12: 0.95 | M12: -0.15751706 | N12: -0.071228007 | O12: 0.11435142
A13: 7 | B13: Clout | C13: -0.11301494 | D13: 0.95 | E13: -0.15739166 | F13: -0.06870485 | G13: 0.11301494 | I13: 7 | J13: negate | K13: 0.08186493 | L13: 0.95 | M13: 0.042432642 | N13: 0.12142791 | O13: 0.08186493
A14: 8 | B14: risk | C14: -0.08593666 | D14: 0.95 | E14: -0.12533988 | F14: -0.04681657 | G14: 0.08593666 | I14: 8 | J14: (Intercept) | K14: 0.04750237 | L14: 0.95 | M14: 0.009901088 | N14: 0.085081974 | O14: 0.04750237
A15: 9 | B15: negate | C15: 0.07210447 | D15: 0.95 | E15: 0.03129935 | F15: 0.11302553 | G15: 0.07210447 | I15: 9 | J15: risk | K15: -0.03214886 | L15: 0.95 | M15: -0.07038675 | N15: 0.006010471 | O15: 0.03214886
A16: Showing 1 to 9 of 9 entries, 6 total columns | I16: Showing 1 to 9 of 9 entries, 6 total columns
A19: COMBINED - 8 VARIABLES PLUS ASSENT DIFF
A20: Llama-3.3-70B-Instruct | I20: Qwen2.5-72B-Instruct | R20: Claude | S20: GPT-4o | T20: Deepseek-r1
A21: AUC | B21: 0.7237 | C21: =B21-B3 -> 0.0292 | I21: AUC | J21: 0.7116 | K21: =J21-J3 -> 0.035 | Q21: AUC | R21: ='Combined GLM'!B54 -> 0.7331 | S21: ='Combined GLM'!J54 -> 0.6988 | T21: ='Combined GLM'!R54 -> 0.6899
Q22: Diff from State | R22: =R21-R3 -> 0.0315 | S22: =S21-S3 -> 0.0247 | T22: =T21-T3 -> 0.0092
B23: Parameter | C23: Std_Coefficient | D23: CI | E23: CI_low | F23: CI_high | G23: abs_coef | J23: Parameter | K23: Std_Coefficient | L23: CI | M23: CI_low | N23: CI_high | O23: abs_coef
A25: 1 | B25: assent | C25: -0.85925037 | D25: 0.95 | E25: -0.93629338 | F25: -0.78394467 | G25: 0.85925037 | I25: 1 | J25: assent | K25: -0.9907246 | L25: 0.95 | M25: -1.0629152 | N25: -0.92010843 | O25: 0.9907246
A26: 2 | B26: assent_diff | C26: 0.53845719 | D26: 0.95 | E26: 0.4679193 | F26: 0.61079806 | G26: 0.53845719 | I26: 2 | J26: assent_diff | K26: 0.53317198 | L26: 0.95 | M26: 0.46980975 | N26: 0.59780593 | O26: 0.53317198
A27: 3 | B27: Tone | C27: 0.413618 | D27: 0.95 | E27: 0.36675813 | F27: 0.4607419 | G27: 0.413618 | I27: 3 | J27: Tone | K27: 0.37132334 | L27: 0.95 | M27: 0.32444789 | N27: 0.4184342 | O27: 0.37132334
A28: 4 | B28: adj | C28: -0.3311908 | D28: 0.95 | E28: -0.3773041 | F28: -0.2853437 | G28: 0.3311908 | I28: 4 | J28: adj | K28: -0.21385109 | L28: 0.95 | M28: -0.25779501 | N28: -0.17007304 | O28: 0.21385109
A29: 5 | B29: (Intercept) | C29: -0.3298512 | D29: 0.95 | E29: -0.37431776 | F29: -0.28560143 | G29: 0.3298512 | I29: 5 | J29: moral | K29: 0.1558314 | L29: 0.95 | M29: 0.11168734 | N29: 0.20026831 | O29: 0.1558314
A30: 6 | B30: we | C30: 0.20667896 | D30: 0.95 | E30: 0.15964889 | F30: 0.25460727 | G30: 0.20667896 | I30: 6 | J30: (Intercept) | K30: -0.14668785 | L30: 0.95 | M30: -0.19028917 | N30: -0.1032439 | O30: 0.14668785
A31: 7 | B31: moral | C31: 0.16687646 | D31: 0.95 | E31: 0.12297928 | F31: 0.21084241 | G31: 0.16687646 | I31: 7 | J31: we | K31: 0.08561527 | L31: 0.95 | M31: 0.041932752 | N31: 0.13023097 | O31: 0.08561527
A32: 8 | B32: risk | C32: -0.08313861 | D32: 0.95 | E32: -0.12892491 | F32: -0.03782369 | G32: 0.08313861 | I32: 8 | J32: Clout | K32: -0.05244609 | L32: 0.95 | M32: -0.10147659 | N32: -0.003433115 | O32: 0.05244609
A33: 9 | B33: Clout | C33: -0.07031654 | D33: 0.95 | E33: -0.12068341 | F33: -0.020021 | G33: 0.07031654 | I33: 9 | J33: negate | K33: 0.04371777 | L33: 0.95 | M33: -0.000954451 | N33: 0.088481951 | O33: 0.04371777
A34: 10 | B34: negate | C34: 0.06322199 | D34: 0.95 | E34: 0.01621767 | F34: 0.1102787 | G34: 0.06322199 | I34: 10 | J34: risk | K34: -0.02038853 | L34: 0.95 | M34: -0.064472979 | N34: 0.023559337 | O34: 0.02038853
A35: Showing 1 to 10 of 10 entries, 6 total columns | I35: Showing 1 to 10 of 10 entries, 6 total columns
A37: STATE ONLY - 5 VARIABLES
A38: Llama-3.3-70B-Instruct | I38: Qwen2.5-72B-Instruct | R38: Claude | S38: GPT-4o | T38: Deepseek-r1
A39: AUC | B39: 0.6576 | I39: AUC | J39: 0.6301 | Q39: AUC | R39: ='State GLM'!B103 -> 0.6978 | S39: ='State GLM'!J103 -> 0.6549 | T39: ='State GLM'!R103 -> 0.658
B41: Parameter | C41: Std_Coefficient | D41: CI | E41: CI_low | F41: CI_high | G41: abs_coef | J41: Parameter | K41: Std_Coefficient | L41: CI | M41: CI_low | N41: CI_high | O41: abs_coef
A43: 1 | B43: assent | C43: -0.5087118 | D43: 0.95 | E43: -0.55676542 | F43: -0.46170558 | G43: 0.5087118 | I43: 1 | J43: assent | K43: -0.5643217 | L43: 0.95 | M43: -0.61042546 | N43: -0.51914404 | O43: 0.5643217
A44: 2 | B44: adj | C44: -0.23830485 | D44: 0.95 | E44: -0.27629752 | F44: -0.20045219 | G44: 0.23830485 | I44: 2 | J44: adj | K44: -0.157349 | L44: 0.95 | M44: -0.19443526 | N44: -0.12036091 | O44: 0.157349
A45: 3 | B45: we | C45: 0.18979516 | D45: 0.95 | E45: 0.14947782 | F45: 0.23102362 | G45: 0.18979516 | I45: 3 | J45: we | K45: 0.1098057 | L45: 0.95 | M45: 0.07041356 | N45: 0.15031847 | O45: 0.1098057
A46: 4 | B46: risk | C46: -0.11110196 | D46: 0.95 | E46: -0.14940049 | F46: -0.07308743 | G46: 0.11110196 | I46: 4 | J46: negate | K46: 0.08599826 | L46: 0.95 | M46: 0.04865202 | N46: 0.12349723 | O46: 0.08599826
